{
 "cells": [
  {
   "cell_type": "code",
   "execution_count": 5,
   "metadata": {},
   "outputs": [
    {
     "name": "stdout",
     "output_type": "stream",
     "text": [
      "Requirement already satisfied: pillow in c:\\users\\sedag\\appdata\\local\\programs\\python\\python39\\lib\\site-packages (8.4.0)\n",
      "Note: you may need to restart the kernel to use updated packages.\n"
     ]
    },
    {
     "name": "stderr",
     "output_type": "stream",
     "text": [
      "WARNING: You are using pip version 21.1.3; however, version 22.3.1 is available.\n",
      "You should consider upgrading via the 'c:\\users\\sedag\\appdata\\local\\programs\\python\\python39\\python.exe -m pip install --upgrade pip' command.\n"
     ]
    }
   ],
   "source": [
    "pip install pillow"
   ]
  },
  {
   "cell_type": "code",
   "execution_count": 11,
   "metadata": {},
   "outputs": [
    {
     "name": "stdout",
     "output_type": "stream",
     "text": [
      "Requirement already satisfied: cmake in c:\\users\\sedag\\appdata\\local\\programs\\python\\python39\\lib\\site-packages (3.25.0)\n",
      "Note: you may need to restart the kernel to use updated packages.\n"
     ]
    }
   ],
   "source": [
    "pip install cmake"
   ]
  },
  {
   "cell_type": "code",
   "execution_count": 13,
   "metadata": {},
   "outputs": [
    {
     "name": "stdout",
     "output_type": "stream",
     "text": [
      "Collecting dlibNote: you may need to restart the kernel to use updated packages.\n",
      "  Using cached dlib-19.24.0.tar.gz (3.2 MB)\n",
      "  Preparing metadata (setup.py): started\n"
     ]
    },
    {
     "name": "stderr",
     "output_type": "stream",
     "text": [
      "  error: subprocess-exited-with-error\n",
      "  \n",
      "  python setup.py bdist_wheel did not run successfully.\n",
      "  exit code: 1\n"
     ]
    },
    {
     "name": "stdout",
     "output_type": "stream",
     "text": [
      "\n",
      "  Preparing metadata (setup.py): finished with status 'done'\n",
      "Building wheels for collected packages: dlib\n",
      "  Building wheel for dlib (setup.py): started\n",
      "  Building wheel for dlib (setup.py): finished with status 'error'\n",
      "  Running setup.py clean for dlib\n",
      "Failed to build dlib\n",
      "Installing collected packages: dlib\n",
      "  Running setup.py install for dlib: started\n",
      "  Running setup.py install for dlib: finished with status 'error'\n"
     ]
    },
    {
     "name": "stderr",
     "output_type": "stream",
     "text": [
      "  \n",
      "  [56 lines of output]\n",
      "  running bdist_wheel\n",
      "  running build\n",
      "  running build_py\n",
      "  package init file 'tools\\python\\dlib\\__init__.py' not found (or not a regular file)\n",
      "  running build_ext\n",
      "  Building extension for Python 3.9.6 (tags/v3.9.6:db3ff76, Jun 28 2021, 15:26:21) [MSC v.1929 64 bit (AMD64)]\n",
      "  Invoking CMake setup: 'cmake C:\\Users\\sedag\\AppData\\Local\\Temp\\pip-install-e7tojph8\\dlib_2223e612138f422c9a71e373c121893a\\tools\\python -DCMAKE_LIBRARY_OUTPUT_DIRECTORY=C:\\Users\\sedag\\AppData\\Local\\Temp\\pip-install-e7tojph8\\dlib_2223e612138f422c9a71e373c121893a\\build\\lib.win-amd64-3.9 -DPYTHON_EXECUTABLE=c:\\users\\sedag\\appdata\\local\\programs\\python\\python39\\python.exe -DCMAKE_LIBRARY_OUTPUT_DIRECTORY_RELEASE=C:\\Users\\sedag\\AppData\\Local\\Temp\\pip-install-e7tojph8\\dlib_2223e612138f422c9a71e373c121893a\\build\\lib.win-amd64-3.9 -A x64'\n",
      "  -- Building for: Visual Studio 16 2019\n",
      "  -- Selecting Windows SDK version  to target Windows 10.0.19043.\n",
      "  -- The C compiler identification is unknown\n",
      "  -- The CXX compiler identification is unknown\n",
      "  CMake Error at CMakeLists.txt:14 (project):\n",
      "    No CMAKE_C_COMPILER could be found.\n",
      "  \n",
      "  \n",
      "  \n",
      "  CMake Error at CMakeLists.txt:14 (project):\n",
      "    No CMAKE_CXX_COMPILER could be found.\n",
      "  \n",
      "  \n",
      "  \n",
      "  -- Configuring incomplete, errors occurred!\n",
      "  See also \"C:/Users/sedag/AppData/Local/Temp/pip-install-e7tojph8/dlib_2223e612138f422c9a71e373c121893a/build/temp.win-amd64-3.9/Release/CMakeFiles/CMakeOutput.log\".\n",
      "  See also \"C:/Users/sedag/AppData/Local/Temp/pip-install-e7tojph8/dlib_2223e612138f422c9a71e373c121893a/build/temp.win-amd64-3.9/Release/CMakeFiles/CMakeError.log\".\n",
      "  Traceback (most recent call last):\n",
      "    File \"<string>\", line 2, in <module>\n",
      "    File \"<pip-setuptools-caller>\", line 34, in <module>\n",
      "    File \"C:\\Users\\sedag\\AppData\\Local\\Temp\\pip-install-e7tojph8\\dlib_2223e612138f422c9a71e373c121893a\\setup.py\", line 222, in <module>\n",
      "      setup(\n",
      "    File \"c:\\users\\sedag\\appdata\\local\\programs\\python\\python39\\lib\\site-packages\\setuptools\\__init__.py\", line 153, in setup\n",
      "      return distutils.core.setup(**attrs)\n",
      "    File \"c:\\users\\sedag\\appdata\\local\\programs\\python\\python39\\lib\\distutils\\core.py\", line 148, in setup\n",
      "      dist.run_commands()\n",
      "    File \"c:\\users\\sedag\\appdata\\local\\programs\\python\\python39\\lib\\distutils\\dist.py\", line 966, in run_commands\n",
      "      self.run_command(cmd)\n",
      "    File \"c:\\users\\sedag\\appdata\\local\\programs\\python\\python39\\lib\\distutils\\dist.py\", line 985, in run_command\n",
      "      cmd_obj.run()\n",
      "    File \"c:\\users\\sedag\\appdata\\local\\programs\\python\\python39\\lib\\site-packages\\wheel\\bdist_wheel.py\", line 299, in run\n",
      "      self.run_command('build')\n",
      "    File \"c:\\users\\sedag\\appdata\\local\\programs\\python\\python39\\lib\\distutils\\cmd.py\", line 313, in run_command\n",
      "      self.distribution.run_command(command)\n",
      "    File \"c:\\users\\sedag\\appdata\\local\\programs\\python\\python39\\lib\\distutils\\dist.py\", line 985, in run_command\n",
      "      cmd_obj.run()\n",
      "    File \"c:\\users\\sedag\\appdata\\local\\programs\\python\\python39\\lib\\distutils\\command\\build.py\", line 135, in run\n",
      "      self.run_command(cmd_name)\n",
      "    File \"c:\\users\\sedag\\appdata\\local\\programs\\python\\python39\\lib\\distutils\\cmd.py\", line 313, in run_command\n",
      "      self.distribution.run_command(command)\n",
      "    File \"c:\\users\\sedag\\appdata\\local\\programs\\python\\python39\\lib\\distutils\\dist.py\", line 985, in run_command\n",
      "      cmd_obj.run()\n",
      "    File \"C:\\Users\\sedag\\AppData\\Local\\Temp\\pip-install-e7tojph8\\dlib_2223e612138f422c9a71e373c121893a\\setup.py\", line 134, in run\n",
      "      self.build_extension(ext)\n",
      "    File \"C:\\Users\\sedag\\AppData\\Local\\Temp\\pip-install-e7tojph8\\dlib_2223e612138f422c9a71e373c121893a\\setup.py\", line 171, in build_extension\n",
      "      subprocess.check_call(cmake_setup, cwd=build_folder)\n",
      "    File \"c:\\users\\sedag\\appdata\\local\\programs\\python\\python39\\lib\\subprocess.py\", line 373, in check_call\n",
      "      raise CalledProcessError(retcode, cmd)\n",
      "  subprocess.CalledProcessError: Command '['cmake', 'C:\\\\Users\\\\sedag\\\\AppData\\\\Local\\\\Temp\\\\pip-install-e7tojph8\\\\dlib_2223e612138f422c9a71e373c121893a\\\\tools\\\\python', '-DCMAKE_LIBRARY_OUTPUT_DIRECTORY=C:\\\\Users\\\\sedag\\\\AppData\\\\Local\\\\Temp\\\\pip-install-e7tojph8\\\\dlib_2223e612138f422c9a71e373c121893a\\\\build\\\\lib.win-amd64-3.9', '-DPYTHON_EXECUTABLE=c:\\\\users\\\\sedag\\\\appdata\\\\local\\\\programs\\\\python\\\\python39\\\\python.exe', '-DCMAKE_LIBRARY_OUTPUT_DIRECTORY_RELEASE=C:\\\\Users\\\\sedag\\\\AppData\\\\Local\\\\Temp\\\\pip-install-e7tojph8\\\\dlib_2223e612138f422c9a71e373c121893a\\\\build\\\\lib.win-amd64-3.9', '-A', 'x64']' returned non-zero exit status 1.\n",
      "  [end of output]\n",
      "  \n",
      "  note: This error originates from a subprocess, and is likely not a problem with pip.\n",
      "  ERROR: Failed building wheel for dlib\n",
      "  error: subprocess-exited-with-error\n",
      "  \n",
      "  Running setup.py install for dlib did not run successfully.\n",
      "  exit code: 1\n",
      "  \n",
      "  [58 lines of output]\n",
      "  running install\n",
      "  running build\n",
      "  running build_py\n",
      "  package init file 'tools\\python\\dlib\\__init__.py' not found (or not a regular file)\n",
      "  running build_ext\n",
      "  Building extension for Python 3.9.6 (tags/v3.9.6:db3ff76, Jun 28 2021, 15:26:21) [MSC v.1929 64 bit (AMD64)]\n",
      "  Invoking CMake setup: 'cmake C:\\Users\\sedag\\AppData\\Local\\Temp\\pip-install-e7tojph8\\dlib_2223e612138f422c9a71e373c121893a\\tools\\python -DCMAKE_LIBRARY_OUTPUT_DIRECTORY=C:\\Users\\sedag\\AppData\\Local\\Temp\\pip-install-e7tojph8\\dlib_2223e612138f422c9a71e373c121893a\\build\\lib.win-amd64-3.9 -DPYTHON_EXECUTABLE=c:\\users\\sedag\\appdata\\local\\programs\\python\\python39\\python.exe -DCMAKE_LIBRARY_OUTPUT_DIRECTORY_RELEASE=C:\\Users\\sedag\\AppData\\Local\\Temp\\pip-install-e7tojph8\\dlib_2223e612138f422c9a71e373c121893a\\build\\lib.win-amd64-3.9 -A x64'\n",
      "  -- Building for: Visual Studio 16 2019\n",
      "  -- Selecting Windows SDK version  to target Windows 10.0.19043.\n",
      "  -- The C compiler identification is unknown\n",
      "  -- The CXX compiler identification is unknown\n",
      "  CMake Error at CMakeLists.txt:14 (project):\n",
      "    No CMAKE_C_COMPILER could be found.\n",
      "  \n",
      "  \n",
      "  \n",
      "  CMake Error at CMakeLists.txt:14 (project):\n",
      "    No CMAKE_CXX_COMPILER could be found.\n",
      "  \n",
      "  \n",
      "  \n",
      "  -- Configuring incomplete, errors occurred!\n",
      "  See also \"C:/Users/sedag/AppData/Local/Temp/pip-install-e7tojph8/dlib_2223e612138f422c9a71e373c121893a/build/temp.win-amd64-3.9/Release/CMakeFiles/CMakeOutput.log\".\n",
      "  See also \"C:/Users/sedag/AppData/Local/Temp/pip-install-e7tojph8/dlib_2223e612138f422c9a71e373c121893a/build/temp.win-amd64-3.9/Release/CMakeFiles/CMakeError.log\".\n",
      "  Traceback (most recent call last):\n",
      "    File \"<string>\", line 2, in <module>\n",
      "    File \"<pip-setuptools-caller>\", line 34, in <module>\n",
      "    File \"C:\\Users\\sedag\\AppData\\Local\\Temp\\pip-install-e7tojph8\\dlib_2223e612138f422c9a71e373c121893a\\setup.py\", line 222, in <module>\n",
      "      setup(\n",
      "    File \"c:\\users\\sedag\\appdata\\local\\programs\\python\\python39\\lib\\site-packages\\setuptools\\__init__.py\", line 153, in setup\n",
      "      return distutils.core.setup(**attrs)\n",
      "    File \"c:\\users\\sedag\\appdata\\local\\programs\\python\\python39\\lib\\distutils\\core.py\", line 148, in setup\n",
      "      dist.run_commands()\n",
      "    File \"c:\\users\\sedag\\appdata\\local\\programs\\python\\python39\\lib\\distutils\\dist.py\", line 966, in run_commands\n",
      "      self.run_command(cmd)\n",
      "    File \"c:\\users\\sedag\\appdata\\local\\programs\\python\\python39\\lib\\distutils\\dist.py\", line 985, in run_command\n",
      "      cmd_obj.run()\n",
      "    File \"c:\\users\\sedag\\appdata\\local\\programs\\python\\python39\\lib\\site-packages\\setuptools\\command\\install.py\", line 61, in run\n",
      "      return orig.install.run(self)\n",
      "    File \"c:\\users\\sedag\\appdata\\local\\programs\\python\\python39\\lib\\distutils\\command\\install.py\", line 546, in run\n",
      "      self.run_command('build')\n",
      "    File \"c:\\users\\sedag\\appdata\\local\\programs\\python\\python39\\lib\\distutils\\cmd.py\", line 313, in run_command\n",
      "      self.distribution.run_command(command)\n",
      "    File \"c:\\users\\sedag\\appdata\\local\\programs\\python\\python39\\lib\\distutils\\dist.py\", line 985, in run_command\n",
      "      cmd_obj.run()\n",
      "    File \"c:\\users\\sedag\\appdata\\local\\programs\\python\\python39\\lib\\distutils\\command\\build.py\", line 135, in run\n",
      "      self.run_command(cmd_name)\n",
      "    File \"c:\\users\\sedag\\appdata\\local\\programs\\python\\python39\\lib\\distutils\\cmd.py\", line 313, in run_command\n",
      "      self.distribution.run_command(command)\n",
      "    File \"c:\\users\\sedag\\appdata\\local\\programs\\python\\python39\\lib\\distutils\\dist.py\", line 985, in run_command\n",
      "      cmd_obj.run()\n",
      "    File \"C:\\Users\\sedag\\AppData\\Local\\Temp\\pip-install-e7tojph8\\dlib_2223e612138f422c9a71e373c121893a\\setup.py\", line 134, in run\n",
      "      self.build_extension(ext)\n",
      "    File \"C:\\Users\\sedag\\AppData\\Local\\Temp\\pip-install-e7tojph8\\dlib_2223e612138f422c9a71e373c121893a\\setup.py\", line 171, in build_extension\n",
      "      subprocess.check_call(cmake_setup, cwd=build_folder)\n",
      "    File \"c:\\users\\sedag\\appdata\\local\\programs\\python\\python39\\lib\\subprocess.py\", line 373, in check_call\n",
      "      raise CalledProcessError(retcode, cmd)\n",
      "  subprocess.CalledProcessError: Command '['cmake', 'C:\\\\Users\\\\sedag\\\\AppData\\\\Local\\\\Temp\\\\pip-install-e7tojph8\\\\dlib_2223e612138f422c9a71e373c121893a\\\\tools\\\\python', '-DCMAKE_LIBRARY_OUTPUT_DIRECTORY=C:\\\\Users\\\\sedag\\\\AppData\\\\Local\\\\Temp\\\\pip-install-e7tojph8\\\\dlib_2223e612138f422c9a71e373c121893a\\\\build\\\\lib.win-amd64-3.9', '-DPYTHON_EXECUTABLE=c:\\\\users\\\\sedag\\\\appdata\\\\local\\\\programs\\\\python\\\\python39\\\\python.exe', '-DCMAKE_LIBRARY_OUTPUT_DIRECTORY_RELEASE=C:\\\\Users\\\\sedag\\\\AppData\\\\Local\\\\Temp\\\\pip-install-e7tojph8\\\\dlib_2223e612138f422c9a71e373c121893a\\\\build\\\\lib.win-amd64-3.9', '-A', 'x64']' returned non-zero exit status 1.\n",
      "  [end of output]\n",
      "  \n",
      "  note: This error originates from a subprocess, and is likely not a problem with pip.\n",
      "error: legacy-install-failure\n",
      "\n",
      "Encountered error while trying to install package.\n",
      "\n",
      "dlib\n",
      "\n",
      "note: This is an issue with the package mentioned above, not pip.\n",
      "hint: See above for output from the failure.\n"
     ]
    }
   ],
   "source": [
    "pip install dlib"
   ]
  },
  {
   "cell_type": "code",
   "execution_count": 14,
   "metadata": {},
   "outputs": [
    {
     "name": "stdout",
     "output_type": "stream",
     "text": [
      "Collecting face_recognition\n",
      "  Using cached face_recognition-1.3.0-py2.py3-none-any.whl (15 kB)\n",
      "Collecting dlib>=19.7\n",
      "  Using cached dlib-19.24.0.tar.gz (3.2 MB)\n",
      "  Preparing metadata (setup.py): started\n",
      "  Preparing metadata (setup.py): finished with status 'done'\n",
      "Collecting Click>=6.0\n",
      "  Using cached click-8.1.3-py3-none-any.whl (96 kB)\n",
      "Requirement already satisfied: numpy in c:\\users\\sedag\\appdata\\local\\programs\\python\\python39\\lib\\site-packages (from face_recognition) (1.21.4)\n",
      "Requirement already satisfied: Pillow in c:\\users\\sedag\\appdata\\local\\programs\\python\\python39\\lib\\site-packages (from face_recognition) (8.4.0)\n",
      "Requirement already satisfied: face-recognition-models>=0.3.0 in c:\\users\\sedag\\appdata\\local\\programs\\python\\python39\\lib\\site-packages (from face_recognition) (0.3.0)\n",
      "Requirement already satisfied: colorama in c:\\users\\sedag\\appdata\\local\\programs\\python\\python39\\lib\\site-packages (from Click>=6.0->face_recognition) (0.4.4)\n",
      "Building wheels for collected packages: dlib\n",
      "  Building wheel for dlib (setup.py): started\n",
      "  Building wheel for dlib (setup.py): finished with status 'error'\n",
      "  Running setup.py clean for dlib\n",
      "Failed to build dlib\n",
      "Installing collected packages: dlib, Click, face_recognition\n",
      "  Running setup.py install for dlib: started\n",
      "  Running setup.py install for dlib: finished with status 'error'\n",
      "Note: you may need to restart the kernel to use updated packages.\n"
     ]
    },
    {
     "name": "stderr",
     "output_type": "stream",
     "text": [
      "  error: subprocess-exited-with-error\n",
      "  \n",
      "  python setup.py bdist_wheel did not run successfully.\n",
      "  exit code: 1\n",
      "  \n",
      "  [56 lines of output]\n",
      "  running bdist_wheel\n",
      "  running build\n",
      "  running build_py\n",
      "  package init file 'tools\\python\\dlib\\__init__.py' not found (or not a regular file)\n",
      "  running build_ext\n",
      "  Building extension for Python 3.9.6 (tags/v3.9.6:db3ff76, Jun 28 2021, 15:26:21) [MSC v.1929 64 bit (AMD64)]\n",
      "  Invoking CMake setup: 'cmake C:\\Users\\sedag\\AppData\\Local\\Temp\\pip-install-o62lzuhb\\dlib_5116871591e04b6faf15937f73265460\\tools\\python -DCMAKE_LIBRARY_OUTPUT_DIRECTORY=C:\\Users\\sedag\\AppData\\Local\\Temp\\pip-install-o62lzuhb\\dlib_5116871591e04b6faf15937f73265460\\build\\lib.win-amd64-3.9 -DPYTHON_EXECUTABLE=c:\\users\\sedag\\appdata\\local\\programs\\python\\python39\\python.exe -DCMAKE_LIBRARY_OUTPUT_DIRECTORY_RELEASE=C:\\Users\\sedag\\AppData\\Local\\Temp\\pip-install-o62lzuhb\\dlib_5116871591e04b6faf15937f73265460\\build\\lib.win-amd64-3.9 -A x64'\n",
      "  -- Building for: Visual Studio 16 2019\n",
      "  -- Selecting Windows SDK version  to target Windows 10.0.19043.\n",
      "  -- The C compiler identification is unknown\n",
      "  -- The CXX compiler identification is unknown\n",
      "  CMake Error at CMakeLists.txt:14 (project):\n",
      "    No CMAKE_C_COMPILER could be found.\n",
      "  \n",
      "  \n",
      "  \n",
      "  CMake Error at CMakeLists.txt:14 (project):\n",
      "    No CMAKE_CXX_COMPILER could be found.\n",
      "  \n",
      "  \n",
      "  \n",
      "  -- Configuring incomplete, errors occurred!\n",
      "  See also \"C:/Users/sedag/AppData/Local/Temp/pip-install-o62lzuhb/dlib_5116871591e04b6faf15937f73265460/build/temp.win-amd64-3.9/Release/CMakeFiles/CMakeOutput.log\".\n",
      "  See also \"C:/Users/sedag/AppData/Local/Temp/pip-install-o62lzuhb/dlib_5116871591e04b6faf15937f73265460/build/temp.win-amd64-3.9/Release/CMakeFiles/CMakeError.log\".\n",
      "  Traceback (most recent call last):\n",
      "    File \"<string>\", line 2, in <module>\n",
      "    File \"<pip-setuptools-caller>\", line 34, in <module>\n",
      "    File \"C:\\Users\\sedag\\AppData\\Local\\Temp\\pip-install-o62lzuhb\\dlib_5116871591e04b6faf15937f73265460\\setup.py\", line 222, in <module>\n",
      "      setup(\n",
      "    File \"c:\\users\\sedag\\appdata\\local\\programs\\python\\python39\\lib\\site-packages\\setuptools\\__init__.py\", line 153, in setup\n",
      "      return distutils.core.setup(**attrs)\n",
      "    File \"c:\\users\\sedag\\appdata\\local\\programs\\python\\python39\\lib\\distutils\\core.py\", line 148, in setup\n",
      "      dist.run_commands()\n",
      "    File \"c:\\users\\sedag\\appdata\\local\\programs\\python\\python39\\lib\\distutils\\dist.py\", line 966, in run_commands\n",
      "      self.run_command(cmd)\n",
      "    File \"c:\\users\\sedag\\appdata\\local\\programs\\python\\python39\\lib\\distutils\\dist.py\", line 985, in run_command\n",
      "      cmd_obj.run()\n",
      "    File \"c:\\users\\sedag\\appdata\\local\\programs\\python\\python39\\lib\\site-packages\\wheel\\bdist_wheel.py\", line 299, in run\n",
      "      self.run_command('build')\n",
      "    File \"c:\\users\\sedag\\appdata\\local\\programs\\python\\python39\\lib\\distutils\\cmd.py\", line 313, in run_command\n",
      "      self.distribution.run_command(command)\n",
      "    File \"c:\\users\\sedag\\appdata\\local\\programs\\python\\python39\\lib\\distutils\\dist.py\", line 985, in run_command\n",
      "      cmd_obj.run()\n",
      "    File \"c:\\users\\sedag\\appdata\\local\\programs\\python\\python39\\lib\\distutils\\command\\build.py\", line 135, in run\n",
      "      self.run_command(cmd_name)\n",
      "    File \"c:\\users\\sedag\\appdata\\local\\programs\\python\\python39\\lib\\distutils\\cmd.py\", line 313, in run_command\n",
      "      self.distribution.run_command(command)\n",
      "    File \"c:\\users\\sedag\\appdata\\local\\programs\\python\\python39\\lib\\distutils\\dist.py\", line 985, in run_command\n",
      "      cmd_obj.run()\n",
      "    File \"C:\\Users\\sedag\\AppData\\Local\\Temp\\pip-install-o62lzuhb\\dlib_5116871591e04b6faf15937f73265460\\setup.py\", line 134, in run\n",
      "      self.build_extension(ext)\n",
      "    File \"C:\\Users\\sedag\\AppData\\Local\\Temp\\pip-install-o62lzuhb\\dlib_5116871591e04b6faf15937f73265460\\setup.py\", line 171, in build_extension\n",
      "      subprocess.check_call(cmake_setup, cwd=build_folder)\n",
      "    File \"c:\\users\\sedag\\appdata\\local\\programs\\python\\python39\\lib\\subprocess.py\", line 373, in check_call\n",
      "      raise CalledProcessError(retcode, cmd)\n",
      "  subprocess.CalledProcessError: Command '['cmake', 'C:\\\\Users\\\\sedag\\\\AppData\\\\Local\\\\Temp\\\\pip-install-o62lzuhb\\\\dlib_5116871591e04b6faf15937f73265460\\\\tools\\\\python', '-DCMAKE_LIBRARY_OUTPUT_DIRECTORY=C:\\\\Users\\\\sedag\\\\AppData\\\\Local\\\\Temp\\\\pip-install-o62lzuhb\\\\dlib_5116871591e04b6faf15937f73265460\\\\build\\\\lib.win-amd64-3.9', '-DPYTHON_EXECUTABLE=c:\\\\users\\\\sedag\\\\appdata\\\\local\\\\programs\\\\python\\\\python39\\\\python.exe', '-DCMAKE_LIBRARY_OUTPUT_DIRECTORY_RELEASE=C:\\\\Users\\\\sedag\\\\AppData\\\\Local\\\\Temp\\\\pip-install-o62lzuhb\\\\dlib_5116871591e04b6faf15937f73265460\\\\build\\\\lib.win-amd64-3.9', '-A', 'x64']' returned non-zero exit status 1.\n",
      "  [end of output]\n",
      "  \n",
      "  note: This error originates from a subprocess, and is likely not a problem with pip.\n",
      "  ERROR: Failed building wheel for dlib\n",
      "  error: subprocess-exited-with-error\n",
      "  \n",
      "  Running setup.py install for dlib did not run successfully.\n",
      "  exit code: 1\n",
      "  \n",
      "  [58 lines of output]\n",
      "  running install\n",
      "  running build\n",
      "  running build_py\n",
      "  package init file 'tools\\python\\dlib\\__init__.py' not found (or not a regular file)\n",
      "  running build_ext\n",
      "  Building extension for Python 3.9.6 (tags/v3.9.6:db3ff76, Jun 28 2021, 15:26:21) [MSC v.1929 64 bit (AMD64)]\n",
      "  Invoking CMake setup: 'cmake C:\\Users\\sedag\\AppData\\Local\\Temp\\pip-install-o62lzuhb\\dlib_5116871591e04b6faf15937f73265460\\tools\\python -DCMAKE_LIBRARY_OUTPUT_DIRECTORY=C:\\Users\\sedag\\AppData\\Local\\Temp\\pip-install-o62lzuhb\\dlib_5116871591e04b6faf15937f73265460\\build\\lib.win-amd64-3.9 -DPYTHON_EXECUTABLE=c:\\users\\sedag\\appdata\\local\\programs\\python\\python39\\python.exe -DCMAKE_LIBRARY_OUTPUT_DIRECTORY_RELEASE=C:\\Users\\sedag\\AppData\\Local\\Temp\\pip-install-o62lzuhb\\dlib_5116871591e04b6faf15937f73265460\\build\\lib.win-amd64-3.9 -A x64'\n",
      "  -- Building for: Visual Studio 16 2019\n",
      "  -- Selecting Windows SDK version  to target Windows 10.0.19043.\n",
      "  -- The C compiler identification is unknown\n",
      "  -- The CXX compiler identification is unknown\n",
      "  CMake Error at CMakeLists.txt:14 (project):\n",
      "    No CMAKE_C_COMPILER could be found.\n",
      "  \n",
      "  \n",
      "  \n",
      "  CMake Error at CMakeLists.txt:14 (project):\n",
      "    No CMAKE_CXX_COMPILER could be found.\n",
      "  \n",
      "  \n",
      "  \n",
      "  -- Configuring incomplete, errors occurred!\n",
      "  See also \"C:/Users/sedag/AppData/Local/Temp/pip-install-o62lzuhb/dlib_5116871591e04b6faf15937f73265460/build/temp.win-amd64-3.9/Release/CMakeFiles/CMakeOutput.log\".\n",
      "  See also \"C:/Users/sedag/AppData/Local/Temp/pip-install-o62lzuhb/dlib_5116871591e04b6faf15937f73265460/build/temp.win-amd64-3.9/Release/CMakeFiles/CMakeError.log\".\n",
      "  Traceback (most recent call last):\n",
      "    File \"<string>\", line 2, in <module>\n",
      "    File \"<pip-setuptools-caller>\", line 34, in <module>\n",
      "    File \"C:\\Users\\sedag\\AppData\\Local\\Temp\\pip-install-o62lzuhb\\dlib_5116871591e04b6faf15937f73265460\\setup.py\", line 222, in <module>\n",
      "      setup(\n",
      "    File \"c:\\users\\sedag\\appdata\\local\\programs\\python\\python39\\lib\\site-packages\\setuptools\\__init__.py\", line 153, in setup\n",
      "      return distutils.core.setup(**attrs)\n",
      "    File \"c:\\users\\sedag\\appdata\\local\\programs\\python\\python39\\lib\\distutils\\core.py\", line 148, in setup\n",
      "      dist.run_commands()\n",
      "    File \"c:\\users\\sedag\\appdata\\local\\programs\\python\\python39\\lib\\distutils\\dist.py\", line 966, in run_commands\n",
      "      self.run_command(cmd)\n",
      "    File \"c:\\users\\sedag\\appdata\\local\\programs\\python\\python39\\lib\\distutils\\dist.py\", line 985, in run_command\n",
      "      cmd_obj.run()\n",
      "    File \"c:\\users\\sedag\\appdata\\local\\programs\\python\\python39\\lib\\site-packages\\setuptools\\command\\install.py\", line 61, in run\n",
      "      return orig.install.run(self)\n",
      "    File \"c:\\users\\sedag\\appdata\\local\\programs\\python\\python39\\lib\\distutils\\command\\install.py\", line 546, in run\n",
      "      self.run_command('build')\n",
      "    File \"c:\\users\\sedag\\appdata\\local\\programs\\python\\python39\\lib\\distutils\\cmd.py\", line 313, in run_command\n",
      "      self.distribution.run_command(command)\n",
      "    File \"c:\\users\\sedag\\appdata\\local\\programs\\python\\python39\\lib\\distutils\\dist.py\", line 985, in run_command\n",
      "      cmd_obj.run()\n",
      "    File \"c:\\users\\sedag\\appdata\\local\\programs\\python\\python39\\lib\\distutils\\command\\build.py\", line 135, in run\n",
      "      self.run_command(cmd_name)\n",
      "    File \"c:\\users\\sedag\\appdata\\local\\programs\\python\\python39\\lib\\distutils\\cmd.py\", line 313, in run_command\n",
      "      self.distribution.run_command(command)\n",
      "    File \"c:\\users\\sedag\\appdata\\local\\programs\\python\\python39\\lib\\distutils\\dist.py\", line 985, in run_command\n",
      "      cmd_obj.run()\n",
      "    File \"C:\\Users\\sedag\\AppData\\Local\\Temp\\pip-install-o62lzuhb\\dlib_5116871591e04b6faf15937f73265460\\setup.py\", line 134, in run\n",
      "      self.build_extension(ext)\n",
      "    File \"C:\\Users\\sedag\\AppData\\Local\\Temp\\pip-install-o62lzuhb\\dlib_5116871591e04b6faf15937f73265460\\setup.py\", line 171, in build_extension\n",
      "      subprocess.check_call(cmake_setup, cwd=build_folder)\n",
      "    File \"c:\\users\\sedag\\appdata\\local\\programs\\python\\python39\\lib\\subprocess.py\", line 373, in check_call\n",
      "      raise CalledProcessError(retcode, cmd)\n",
      "  subprocess.CalledProcessError: Command '['cmake', 'C:\\\\Users\\\\sedag\\\\AppData\\\\Local\\\\Temp\\\\pip-install-o62lzuhb\\\\dlib_5116871591e04b6faf15937f73265460\\\\tools\\\\python', '-DCMAKE_LIBRARY_OUTPUT_DIRECTORY=C:\\\\Users\\\\sedag\\\\AppData\\\\Local\\\\Temp\\\\pip-install-o62lzuhb\\\\dlib_5116871591e04b6faf15937f73265460\\\\build\\\\lib.win-amd64-3.9', '-DPYTHON_EXECUTABLE=c:\\\\users\\\\sedag\\\\appdata\\\\local\\\\programs\\\\python\\\\python39\\\\python.exe', '-DCMAKE_LIBRARY_OUTPUT_DIRECTORY_RELEASE=C:\\\\Users\\\\sedag\\\\AppData\\\\Local\\\\Temp\\\\pip-install-o62lzuhb\\\\dlib_5116871591e04b6faf15937f73265460\\\\build\\\\lib.win-amd64-3.9', '-A', 'x64']' returned non-zero exit status 1.\n",
      "  [end of output]\n",
      "  \n",
      "  note: This error originates from a subprocess, and is likely not a problem with pip.\n",
      "error: legacy-install-failure\n",
      "\n",
      "Encountered error while trying to install package.\n",
      "\n",
      "dlib\n",
      "\n",
      "note: This is an issue with the package mentioned above, not pip.\n",
      "hint: See above for output from the failure.\n"
     ]
    }
   ],
   "source": [
    "pip install face_recognition"
   ]
  },
  {
   "cell_type": "code",
   "execution_count": 1,
   "metadata": {},
   "outputs": [],
   "source": [
    "from PIL import Image\n",
    "import face_recognition"
   ]
  },
  {
   "cell_type": "code",
   "execution_count": 3,
   "metadata": {},
   "outputs": [
    {
     "name": "stdout",
     "output_type": "stream",
     "text": [
      "I found 1 face(s) in this photograph.\n",
      "A face is located at pixel location Top: 724, Left: 1682, Bottom: 1682, Right: 2640\n"
     ]
    }
   ],
   "source": [
    "image = face_recognition.load_image_file(\"C:/Users/sedag/compare_proj/Deep_Learning_Project/dataset/21600015.jpg\")\n",
    "face_locations = face_recognition.face_locations(image)\n",
    "print(\"I found {} face(s) in this photograph.\".format(len(face_locations)))\n",
    "\n",
    "for face_location in face_locations:\n",
    "\n",
    "    # Print the location of each face in this image\n",
    "    top, right, bottom, left = face_location\n",
    "    print(\"A face is located at pixel location Top: {}, Left: {}, Bottom: {}, Right: {}\".format(top, left, bottom, right))\n",
    "\n",
    "    # You can access the actual face itself like this:\n",
    "    face_image = image[top:bottom, left:right]\n",
    "    pil_image = Image.fromarray(face_image)\n",
    "    pil_image.show()"
   ]
  },
  {
   "cell_type": "code",
   "execution_count": 4,
   "metadata": {},
   "outputs": [
    {
     "name": "stdout",
     "output_type": "stream",
     "text": [
      "I found 1 face(s) in this photograph.\n",
      "The chin in this face has the following points: [(1596, 994), (1604, 1130), (1625, 1268), (1667, 1396), (1731, 1505), (1822, 1584), (1931, 1640), (2054, 1675), (2161, 1675), (2246, 1647), (2314, 1580), (2384, 1505), (2443, 1417), (2491, 1313), (2525, 1205), (2538, 1089), (2530, 973)]\n",
      "The left_eyebrow in this face has the following points: [(1741, 873), (1823, 824), (1925, 811), (2023, 830), (2117, 866)]\n",
      "The right_eyebrow in this face has the following points: [(2317, 865), (2382, 828), (2447, 809), (2513, 808), (2548, 854)]\n",
      "The nose_bridge in this face has the following points: [(2226, 977), (2236, 1065), (2250, 1149), (2263, 1233)]\n",
      "The nose_tip in this face has the following points: [(2137, 1295), (2188, 1302), (2235, 1309), (2273, 1301), (2305, 1285)]\n",
      "The left_eye in this face has the following points: [(1841, 971), (1913, 936), (1989, 939), (2054, 999), (1985, 1009), (1907, 1004)]\n",
      "The right_eye in this face has the following points: [(2311, 991), (2367, 927), (2432, 920), (2477, 954), (2442, 991), (2376, 997)]\n",
      "The top_lip in this face has the following points: [(2036, 1462), (2124, 1428), (2193, 1403), (2228, 1412), (2263, 1396), (2302, 1409), (2334, 1433), (2311, 1436), (2261, 1435), (2226, 1443), (2190, 1444), (2066, 1458)]\n",
      "The bottom_lip in this face has the following points: [(2334, 1433), (2302, 1488), (2266, 1518), (2227, 1528), (2186, 1529), (2120, 1513), (2036, 1462), (2066, 1458), (2193, 1454), (2229, 1452), (2264, 1444), (2311, 1436)]\n"
     ]
    }
   ],
   "source": [
    "from PIL import Image, ImageDraw\n",
    "import face_recognition\n",
    "\n",
    "# Load the jpg file into a numpy array\n",
    "image = face_recognition.load_image_file(\"C:/Users/sedag/compare_proj/Deep_Learning_Project/dataset/21600015.jpg\")\n",
    "\n",
    "# Find all facial features in all the faces in the image\n",
    "face_landmarks_list = face_recognition.face_landmarks(image)\n",
    "\n",
    "print(\"I found {} face(s) in this photograph.\".format(len(face_landmarks_list)))\n",
    "\n",
    "# Create a PIL imagedraw object so we can draw on the picture\n",
    "pil_image = Image.fromarray(image)\n",
    "d = ImageDraw.Draw(pil_image)\n",
    "\n",
    "for face_landmarks in face_landmarks_list:\n",
    "\n",
    "    # Print the location of each facial feature in this image\n",
    "    for facial_feature in face_landmarks.keys():\n",
    "        print(\"The {} in this face has the following points: {}\".format(facial_feature, face_landmarks[facial_feature]))\n",
    "\n",
    "    # Let's trace out each facial feature in the image with a line!\n",
    "    for facial_feature in face_landmarks.keys():\n",
    "        d.line(face_landmarks[facial_feature], width=5)\n",
    "\n",
    "# Show the picture\n",
    "pil_image.show()"
   ]
  },
  {
   "cell_type": "code",
   "execution_count": 2,
   "metadata": {},
   "outputs": [
    {
     "name": "stdout",
     "output_type": "stream",
     "text": [
      "Collecting tqdm\n",
      "  Downloading tqdm-4.64.1-py2.py3-none-any.whl (78 kB)\n",
      "     ---------------------------------------- 78.5/78.5 kB 4.3 MB/s eta 0:00:00\n",
      "Requirement already satisfied: colorama in c:\\users\\sedag\\appdata\\local\\programs\\python\\python39\\lib\\site-packages (from tqdm) (0.4.4)\n",
      "Installing collected packages: tqdm\n",
      "Successfully installed tqdm-4.64.1\n",
      "Note: you may need to restart the kernel to use updated packages.\n"
     ]
    }
   ],
   "source": [
    "pip install tqdm"
   ]
  },
  {
   "cell_type": "code",
   "execution_count": 4,
   "metadata": {},
   "outputs": [
    {
     "name": "stdout",
     "output_type": "stream",
     "text": [
      "Note: you may need to restart the kernel to use updated packages.\n"
     ]
    },
    {
     "name": "stderr",
     "output_type": "stream",
     "text": [
      "ERROR: Could not find a version that satisfies the requirement time (from versions: none)\n",
      "ERROR: No matching distribution found for time\n"
     ]
    }
   ],
   "source": [
    "pip install time"
   ]
  },
  {
   "cell_type": "code",
   "execution_count": null,
   "metadata": {},
   "outputs": [
    {
     "name": "stdout",
     "output_type": "stream",
     "text": [
      "Training KNN classifier...\n",
      "10\n",
      "20\n",
      "30\n",
      "40\n",
      "50\n",
      "60\n",
      "70\n",
      "80\n",
      "90\n",
      "100\n",
      "110\n",
      "120\n",
      "130\n",
      "140\n",
      "150\n",
      "160\n",
      "170\n",
      "180\n",
      "190\n",
      "200\n",
      "210\n",
      "220\n",
      "230\n",
      "240\n",
      "250\n",
      "260\n",
      "270\n"
     ]
    }
   ],
   "source": [
    "import math\n",
    "from sklearn import neighbors\n",
    "import os\n",
    "import os.path\n",
    "import pickle\n",
    "from PIL import Image, ImageDraw\n",
    "import face_recognition\n",
    "from face_recognition.face_recognition_cli import image_files_in_folder\n",
    "\n",
    "from tqdm import tqdm\n",
    "import time\n",
    "from time import sleep\n",
    "\n",
    "\n",
    "ALLOWED_EXTENSIONS = {'png', 'jpg', 'jpeg'}\n",
    "\n",
    "\n",
    "def train(train_dir, model_save_path='C:/Users/sedag/compare_proj/Deep_Learning_Project/dataset', n_neighbors=None, knn_algo='ball_tree', verbose=False):\n",
    "    \"\"\"\n",
    "    Trains a k-nearest neighbors classifier for face recognition.\n",
    "\n",
    "    :param train_dir: directory that contains a sub-directory for each known person, with its name.\n",
    "\n",
    "     (View in source code to see train_dir example tree structure)\n",
    "\n",
    "     Structure:\n",
    "        <train_dir>/\n",
    "        ├── <person1>/\n",
    "        │   ├── <somename1>.jpeg\n",
    "        │   ├── <somename2>.jpeg\n",
    "        │   ├── ...\n",
    "        ├── <person2>/\n",
    "        │   ├── <somename1>.jpeg\n",
    "        │   └── <somename2>.jpeg\n",
    "        └── ...\n",
    "\n",
    "    :param model_save_path: (optional) path to save model on disk\n",
    "    :param n_neighbors: (optional) number of neighbors to weigh in classification. Chosen automatically if not specified\n",
    "    :param knn_algo: (optional) underlying data structure to support knn.default is ball_tree\n",
    "    :param verbose: verbosity of training\n",
    "    :return: returns knn classifier that was trained on the given data.\n",
    "    \"\"\"\n",
    "    X = []\n",
    "    y = []\n",
    "\n",
    "    # Loop through each person in the training set\n",
    "    for class_dir in os.listdir(train_dir):\n",
    "        if not os.path.isdir(os.path.join(train_dir, class_dir)):\n",
    "            continue\n",
    "\n",
    "        # Loop through each training image for the current person\n",
    "        for img_path in image_files_in_folder(os.path.join(train_dir, class_dir)):\n",
    "                image = face_recognition.load_image_file(img_path)\n",
    "                face_bounding_boxes = face_recognition.face_locations(image)\n",
    "\n",
    "                if len(face_bounding_boxes) != 1:\n",
    "                    # If there are no people (or too many people) in a training image, skip the image.\n",
    "                    if verbose:\n",
    "                        print(\"Image {} not suitable for training: {}\".format(img_path, \"Didn't find a face\" if len(face_bounding_boxes) < 1 else \"Found more than one face\"))\n",
    "                else:\n",
    "                    # Add face encoding for current image to the training set\n",
    "                    X.append(face_recognition.face_encodings(image, known_face_locations=face_bounding_boxes)[0])\n",
    "                    y.append(class_dir)\n",
    "                    if (len(y)%10==0):\n",
    "                        print(len(y))\n",
    "\n",
    "    # Determine how many neighbors to use for weighting in the KNN classifier\n",
    "    if n_neighbors is None:\n",
    "        n_neighbors = int(round(math.sqrt(len(X))))\n",
    "        if verbose:\n",
    "            print(\"Chose n_neighbors automatically:\", n_neighbors)\n",
    "\n",
    "    # Create and train the KNN classifier\n",
    "    knn_clf = neighbors.KNeighborsClassifier(n_neighbors=n_neighbors, algorithm=knn_algo, weights='distance')\n",
    "    knn_clf.fit(X, y)\n",
    "\n",
    "    # Save the trained KNN classifier\n",
    "    if model_save_path is not None:\n",
    "        with open(model_save_path, 'wb') as f:\n",
    "            pickle.dump(knn_clf, f)\n",
    "\n",
    "    return knn_clf\n",
    "\n",
    "\n",
    "def predict(X_img_path, knn_clf=None, model_path=None, distance_threshold=0.6):\n",
    "    \"\"\"\n",
    "    Recognizes faces in given image using a trained KNN classifier\n",
    "\n",
    "    :param X_img_path: path to image to be recognized\n",
    "    :param knn_clf: (optional) a knn classifier object. if not specified, model_save_path must be specified.\n",
    "    :param model_path: (optional) path to a pickled knn classifier. if not specified, model_save_path must be knn_clf.\n",
    "    :param distance_threshold: (optional) distance threshold for face classification. the larger it is, the more chance\n",
    "           of mis-classifying an unknown person as a known one.\n",
    "    :return: a list of names and face locations for the recognized faces in the image: [(name, bounding box), ...].\n",
    "        For faces of unrecognized persons, the name 'unknown' will be returned.\n",
    "    \"\"\"\n",
    "    if not os.path.isfile(X_img_path) or os.path.splitext(X_img_path)[1][1:] not in ALLOWED_EXTENSIONS:\n",
    "        raise Exception(\"Invalid image path: {}\".format(X_img_path))\n",
    "\n",
    "    if knn_clf is None and model_path is None:\n",
    "        raise Exception(\"Must supply knn classifier either thourgh knn_clf or model_path\")\n",
    "\n",
    "    # Load a trained KNN model (if one was passed in)\n",
    "    if knn_clf is None:\n",
    "        with open(model_path, 'rb') as f:\n",
    "            knn_clf = pickle.load(f)\n",
    "\n",
    "    # Load image file and find face locations\n",
    "    X_img = face_recognition.load_image_file(X_img_path)\n",
    "    X_face_locations = face_recognition.face_locations(X_img)\n",
    "\n",
    "    # If no faces are found in the image, return an empty result.\n",
    "    if len(X_face_locations) == 0:\n",
    "        return []\n",
    "\n",
    "    # Find encodings for faces in the test iamge\n",
    "    faces_encodings = face_recognition.face_encodings(X_img, known_face_locations=X_face_locations)\n",
    "\n",
    "    # Use the KNN model to find the best matches for the test face\n",
    "    closest_distances = knn_clf.kneighbors(faces_encodings, n_neighbors=1)\n",
    "    are_matches = [closest_distances[0][i][0] <= distance_threshold for i in range(len(X_face_locations))]\n",
    "\n",
    "    # Predict classes and remove classifications that aren't within the threshold\n",
    "    return [(pred, loc) if rec else (\"unknown\", loc) for pred, loc, rec in zip(knn_clf.predict(faces_encodings), X_face_locations, are_matches)]\n",
    "\n",
    "\n",
    "def show_prediction_labels_on_image(img_path, predictions):\n",
    "    \"\"\"\n",
    "    Shows the face recognition results visually.\n",
    "\n",
    "    :param img_path: path to image to be recognized\n",
    "    :param predictions: results of the predict function\n",
    "    :return:\n",
    "    \"\"\"\n",
    "    pil_image = Image.open(img_path).convert(\"RGB\")\n",
    "    draw = ImageDraw.Draw(pil_image)\n",
    "\n",
    "    for name, (top, right, bottom, left) in predictions:\n",
    "        # Draw a box around the face using the Pillow module\n",
    "        draw.rectangle(((left, top), (right, bottom)), outline=(0, 0, 255))\n",
    "\n",
    "        # There's a bug in Pillow where it blows up with non-UTF-8 text\n",
    "        # when using the default bitmap font\n",
    "        name = name.encode(\"UTF-8\")\n",
    "\n",
    "        # Draw a label with a name below the face\n",
    "        text_width, text_height = draw.textsize(name)\n",
    "        draw.rectangle(((left, bottom - text_height - 10), (right, bottom)), fill=(0, 0, 255), outline=(0, 0, 255))\n",
    "        draw.text((left + 6, bottom - text_height - 5), name, fill=(255, 255, 255, 255))\n",
    "\n",
    "    # Remove the drawing library from memory as per the Pillow docs\n",
    "    del draw\n",
    "\n",
    "    # Display the resulting image\n",
    "    pil_image.show()\n",
    "\n",
    "\n",
    "if __name__ == \"__main__\":\n",
    "    # STEP 1: Train the KNN classifier and save it to disk\n",
    "    # Once the model is trained and saved, you can skip this step next time.\n",
    "    print(\"Training KNN classifier...\")\n",
    "    classifier = train(\"C:/Users/sedag/compare_proj/Deep_Learning_Project/dataset/training_set\", model_save_path=\"trained_knn_model.clf\", n_neighbors=2)\n",
    "    print(\"Training complete!\")\n",
    "\n",
    "    # STEP 2: Using the trained classifier, make predictions for unknown images\n",
    "    for image_file in os.listdir(\"C:/Users/sedag/compare_proj/Deep_Learning_Project/dataset/test_test\"):\n",
    "        full_file_path = os.path.join(\"C:/Users/sedag/compare_proj/Deep_Learning_Project/dataset/test_test\", image_file)\n",
    "\n",
    "        print(\"Looking for faces in {}\".format(image_file))\n",
    "\n",
    "        # Find all people in the image using a trained classifier model\n",
    "        # Note: You can pass in either a classifier file name or a classifier model instance\n",
    "        predictions = predict(full_file_path, model_path=\"trained_knn_model.clf\")\n",
    "\n",
    "        # Print results on the console\n",
    "        for name, (top, right, bottom, left) in predictions:\n",
    "            print(\"- Found {} at ({}, {})\".format(name, left, top))\n",
    "\n",
    "        # Display results overlaid on an image\n",
    "        show_prediction_labels_on_image(os.path.join(\"C:/Users/sedag/compare_proj/Deep_Learning_Project/dataset/test_test\", image_file), predictions)"
   ]
  },
  {
   "cell_type": "code",
   "execution_count": null,
   "metadata": {},
   "outputs": [],
   "source": []
  }
 ],
 "metadata": {
  "kernelspec": {
   "display_name": "Python 3 (ipykernel)",
   "language": "python",
   "name": "python3"
  },
  "language_info": {
   "codemirror_mode": {
    "name": "ipython",
    "version": 3
   },
   "file_extension": ".py",
   "mimetype": "text/x-python",
   "name": "python",
   "nbconvert_exporter": "python",
   "pygments_lexer": "ipython3",
   "version": "3.9.6"
  },
  "vscode": {
   "interpreter": {
    "hash": "31f2aee4e71d21fbe5cf8b01ff0e069b9275f58929596ceb00d14d90e3e16cd6"
   }
  }
 },
 "nbformat": 4,
 "nbformat_minor": 2
}
